INFO:     Started server process [1]
INFO:     Waiting for application startup.
INFO:     Application startup complete.
INFO:     Uvicorn running on http://0.0.0.0:80 (Press CTRL+C to quit)
ERROR:    Exception in ASGI application
Traceback (most recent call last):
  File "/usr/local/lib/python3.10/site-packages/starlette/responses.py", line 331, in __call__
    stat_result = await anyio.to_thread.run_sync(os.stat, self.path)
ID:  0d08017d-492f-48ac-a46b-ac8c8b74ed35
Filepath:  /usr/src/app/af2b8184-6dfa-419e-a4fd-6f9e3d4daa9c.xlsx
INFO:     172.23.0.6:57488 - "POST /task/excel/uploadfile_with_progress HTTP/1.0" 202 Accepted
ID:  892bc111-1ff5-44c8-b4ec-6fae1ac02010
Filepath:  /usr/src/app/d678393f-7587-4cc0-822c-c446a4f2a33f.xlsx
INFO:     172.23.0.6:57510 - "POST /task/excel/uploadfile_with_progress HTTP/1.0" 202 Accepted
ID:  892bc111-1ff5-44c8-b4ec-6fae1ac02010
Status:  PENDING
INFO:     172.23.0.6:57512 - "GET /queue/892bc111-1ff5-44c8-b4ec-6fae1ac02010 HTTP/1.0" 200 OK
ID:  892bc111-1ff5-44c8-b4ec-6fae1ac02010
Status:  SUCCESS
INFO:     172.23.0.6:57516 - "GET /queue/892bc111-1ff5-44c8-b4ec-6fae1ac02010 HTTP/1.0" 200 OK
ID:  892bc111-1ff5-44c8-b4ec-6fae1ac02010
Status:  SUCCESS
INFO:     172.23.0.6:57518 - "GET /queue/892bc111-1ff5-44c8-b4ec-6fae1ac02010 HTTP/1.0" 500 Internal Server Error
  File "/usr/local/lib/python3.10/site-packages/anyio/to_thread.py", line 31, in run_sync
    return await get_asynclib().run_sync_in_worker_thread(
  File "/usr/local/lib/python3.10/site-packages/anyio/_backends/_asyncio.py", line 937, in run_sync_in_worker_thread
    return await future
  File "/usr/local/lib/python3.10/site-packages/anyio/_backends/_asyncio.py", line 867, in run
    result = context.run(func, *args)
FileNotFoundError: [Errno 2] No such file or directory: '/usr/src/app/edited_file.xlsx'

During handling of the above exception, another exception occurred:

Traceback (most recent call last):
  File "/usr/local/lib/python3.10/site-packages/uvicorn/protocols/http/httptools_impl.py", line 419, in run_asgi
    result = await app(  # type: ignore[func-returns-value]
  File "/usr/local/lib/python3.10/site-packages/uvicorn/middleware/proxy_headers.py", line 78, in __call__
    return await self.app(scope, receive, send)
  File "/usr/local/lib/python3.10/site-packages/fastapi/applications.py", line 270, in __call__
    await super().__call__(scope, receive, send)
  File "/usr/local/lib/python3.10/site-packages/starlette/applications.py", line 124, in __call__
    await self.middleware_stack(scope, receive, send)
  File "/usr/local/lib/python3.10/site-packages/starlette/middleware/errors.py", line 184, in __call__
    raise exc
  File "/usr/local/lib/python3.10/site-packages/starlette/middleware/errors.py", line 162, in __call__
    await self.app(scope, receive, _send)
  File "/usr/local/lib/python3.10/site-packages/starlette/middleware/cors.py", line 84, in __call__
    await self.app(scope, receive, send)
  File "/usr/local/lib/python3.10/site-packages/starlette/middleware/exceptions.py", line 79, in __call__
    raise exc
  File "/usr/local/lib/python3.10/site-packages/starlette/middleware/exceptions.py", line 68, in __call__
    await self.app(scope, receive, sender)
  File "/usr/local/lib/python3.10/site-packages/fastapi/middleware/asyncexitstack.py", line 21, in __call__
    raise e
  File "/usr/local/lib/python3.10/site-packages/fastapi/middleware/asyncexitstack.py", line 18, in __call__
    await self.app(scope, receive, send)
  File "/usr/local/lib/python3.10/site-packages/starlette/routing.py", line 706, in __call__
    await route.handle(scope, receive, send)
  File "/usr/local/lib/python3.10/site-packages/starlette/routing.py", line 276, in handle
    await self.app(scope, receive, send)
  File "/usr/local/lib/python3.10/site-packages/starlette/routing.py", line 69, in app
    await response(scope, receive, send)
  File "/usr/local/lib/python3.10/site-packages/starlette/responses.py", line 334, in __call__
    raise RuntimeError(f"File at path {self.path} does not exist.")
RuntimeError: File at path /usr/src/app/edited_file.xlsx does not exist.
ERROR:    Exception in ASGI application
Traceback (most recent call last):
  File "/usr/local/lib/python3.10/site-packages/starlette/responses.py", line 331, in __call__
    stat_result = await anyio.to_thread.run_sync(os.stat, self.path)
  File "/usr/local/lib/python3.10/site-packages/anyio/to_thread.py", line 31, in run_sync
    return await get_asynclib().run_sync_in_worker_thread(
  File "/usr/local/lib/python3.10/site-packages/anyio/_backends/_asyncio.py", line 937, in run_sync_in_worker_thread
    return await future
  File "/usr/local/lib/python3.10/site-packages/anyio/_backends/_asyncio.py", line 867, in run
    result = context.run(func, *args)
FileNotFoundError: [Errno 2] No such file or directory: '/usr/src/app/edited_file.xlsx'

During handling of the above exception, another exception occurred:

Traceback (most recent call last):
  File "/usr/local/lib/python3.10/site-packages/uvicorn/protocols/http/httptools_impl.py", line 419, in run_asgi
    result = await app(  # type: ignore[func-returns-value]
  File "/usr/local/lib/python3.10/site-packages/uvicorn/middleware/proxy_headers.py", line 78, in __call__
    return await self.app(scope, receive, send)
  File "/usr/local/lib/python3.10/site-packages/fastapi/applications.py", line 270, in __call__
    await super().__call__(scope, receive, send)
  File "/usr/local/lib/python3.10/site-packages/starlette/applications.py", line 124, in __call__
    await self.middleware_stack(scope, receive, send)
  File "/usr/local/lib/python3.10/site-packages/starlette/middleware/errors.py", line 184, in __call__
    raise exc
  File "/usr/local/lib/python3.10/site-packages/starlette/middleware/errors.py", line 162, in __call__
    await self.app(scope, receive, _send)
  File "/usr/local/lib/python3.10/site-packages/starlette/middleware/cors.py", line 84, in __call__
    await self.app(scope, receive, send)
  File "/usr/local/lib/python3.10/site-packages/starlette/middleware/exceptions.py", line 79, in __call__
    raise exc
  File "/usr/local/lib/python3.10/site-packages/starlette/middleware/exceptions.py", line 68, in __call__
    await self.app(scope, receive, sender)
  File "/usr/local/lib/python3.10/site-packages/fastapi/middleware/asyncexitstack.py", line 21, in __call__
    raise e
  File "/usr/local/lib/python3.10/site-packages/fastapi/middleware/asyncexitstack.py", line 18, in __call__
    await self.app(scope, receive, send)
  File "/usr/local/lib/python3.10/site-packages/starlette/routing.py", line 706, in __call__
    await route.handle(scope, receive, send)
  File "/usr/local/lib/python3.10/site-packages/starlette/routing.py", line 276, in handle
    await self.app(scope, receive, send)
  File "/usr/local/lib/python3.10/site-packages/starlette/routing.py", line 69, in app
    await response(scope, receive, send)
  File "/usr/local/lib/python3.10/site-packages/starlette/responses.py", line 334, in __call__
ID:  892bc111-1ff5-44c8-b4ec-6fae1ac02010
Status:  SUCCESS
INFO:     172.23.0.6:57520 - "GET /queue/892bc111-1ff5-44c8-b4ec-6fae1ac02010 HTTP/1.0" 500 Internal Server Error
    raise RuntimeError(f"File at path {self.path} does not exist.")
RuntimeError: File at path /usr/src/app/edited_file.xlsx does not exist.
ERROR:    Exception in ASGI application
Traceback (most recent call last):
  File "/usr/local/lib/python3.10/site-packages/starlette/responses.py", line 331, in __call__
    stat_result = await anyio.to_thread.run_sync(os.stat, self.path)
  File "/usr/local/lib/python3.10/site-packages/anyio/to_thread.py", line 31, in run_sync
    return await get_asynclib().run_sync_in_worker_thread(
  File "/usr/local/lib/python3.10/site-packages/anyio/_backends/_asyncio.py", line 937, in run_sync_in_worker_thread
ID:  892bc111-1ff5-44c8-b4ec-6fae1ac02010
Status:  SUCCESS
INFO:     172.23.0.6:57522 - "GET /queue/892bc111-1ff5-44c8-b4ec-6fae1ac02010 HTTP/1.0" 500 Internal Server Error
    return await future
  File "/usr/local/lib/python3.10/site-packages/anyio/_backends/_asyncio.py", line 867, in run
    result = context.run(func, *args)
FileNotFoundError: [Errno 2] No such file or directory: '/usr/src/app/edited_file.xlsx'

During handling of the above exception, another exception occurred:

Traceback (most recent call last):
  File "/usr/local/lib/python3.10/site-packages/uvicorn/protocols/http/httptools_impl.py", line 419, in run_asgi
    result = await app(  # type: ignore[func-returns-value]
  File "/usr/local/lib/python3.10/site-packages/uvicorn/middleware/proxy_headers.py", line 78, in __call__
    return await self.app(scope, receive, send)
  File "/usr/local/lib/python3.10/site-packages/fastapi/applications.py", line 270, in __call__
    await super().__call__(scope, receive, send)
  File "/usr/local/lib/python3.10/site-packages/starlette/applications.py", line 124, in __call__
    await self.middleware_stack(scope, receive, send)
  File "/usr/local/lib/python3.10/site-packages/starlette/middleware/errors.py", line 184, in __call__
    raise exc
  File "/usr/local/lib/python3.10/site-packages/starlette/middleware/errors.py", line 162, in __call__
    await self.app(scope, receive, _send)
  File "/usr/local/lib/python3.10/site-packages/starlette/middleware/cors.py", line 84, in __call__
    await self.app(scope, receive, send)
  File "/usr/local/lib/python3.10/site-packages/starlette/middleware/exceptions.py", line 79, in __call__
    raise exc
  File "/usr/local/lib/python3.10/site-packages/starlette/middleware/exceptions.py", line 68, in __call__
    await self.app(scope, receive, sender)
  File "/usr/local/lib/python3.10/site-packages/fastapi/middleware/asyncexitstack.py", line 21, in __call__
    raise e
  File "/usr/local/lib/python3.10/site-packages/fastapi/middleware/asyncexitstack.py", line 18, in __call__
    await self.app(scope, receive, send)
  File "/usr/local/lib/python3.10/site-packages/starlette/routing.py", line 706, in __call__
    await route.handle(scope, receive, send)
  File "/usr/local/lib/python3.10/site-packages/starlette/routing.py", line 276, in handle
    await self.app(scope, receive, send)
  File "/usr/local/lib/python3.10/site-packages/starlette/routing.py", line 69, in app
    await response(scope, receive, send)
  File "/usr/local/lib/python3.10/site-packages/starlette/responses.py", line 334, in __call__
    raise RuntimeError(f"File at path {self.path} does not exist.")
RuntimeError: File at path /usr/src/app/edited_file.xlsx does not exist.
ERROR:    Exception in ASGI application
Traceback (most recent call last):
  File "/usr/local/lib/python3.10/site-packages/starlette/responses.py", line 331, in __call__
    stat_result = await anyio.to_thread.run_sync(os.stat, self.path)
  File "/usr/local/lib/python3.10/site-packages/anyio/to_thread.py", line 31, in run_sync
    return await get_asynclib().run_sync_in_worker_thread(
  File "/usr/local/lib/python3.10/site-packages/anyio/_backends/_asyncio.py", line 937, in run_sync_in_worker_thread
    return await future
  File "/usr/local/lib/python3.10/site-packages/anyio/_backends/_asyncio.py", line 867, in run
    result = context.run(func, *args)
FileNotFoundError: [Errno 2] No such file or directory: '/usr/src/app/edited_file.xlsx'

During handling of the above exception, another exception occurred:

Traceback (most recent call last):
ID:  892bc111-1ff5-44c8-b4ec-6fae1ac02010
Status:  SUCCESS
INFO:     172.23.0.6:57524 - "GET /queue/892bc111-1ff5-44c8-b4ec-6fae1ac02010 HTTP/1.0" 500 Internal Server Error
  File "/usr/local/lib/python3.10/site-packages/uvicorn/protocols/http/httptools_impl.py", line 419, in run_asgi
    result = await app(  # type: ignore[func-returns-value]
  File "/usr/local/lib/python3.10/site-packages/uvicorn/middleware/proxy_headers.py", line 78, in __call__
    return await self.app(scope, receive, send)
  File "/usr/local/lib/python3.10/site-packages/fastapi/applications.py", line 270, in __call__
    await super().__call__(scope, receive, send)
  File "/usr/local/lib/python3.10/site-packages/starlette/applications.py", line 124, in __call__
    await self.middleware_stack(scope, receive, send)
  File "/usr/local/lib/python3.10/site-packages/starlette/middleware/errors.py", line 184, in __call__
    raise exc
  File "/usr/local/lib/python3.10/site-packages/starlette/middleware/errors.py", line 162, in __call__
    await self.app(scope, receive, _send)
  File "/usr/local/lib/python3.10/site-packages/starlette/middleware/cors.py", line 84, in __call__
    await self.app(scope, receive, send)
  File "/usr/local/lib/python3.10/site-packages/starlette/middleware/exceptions.py", line 79, in __call__
    raise exc
  File "/usr/local/lib/python3.10/site-packages/starlette/middleware/exceptions.py", line 68, in __call__
    await self.app(scope, receive, sender)
  File "/usr/local/lib/python3.10/site-packages/fastapi/middleware/asyncexitstack.py", line 21, in __call__
    raise e
  File "/usr/local/lib/python3.10/site-packages/fastapi/middleware/asyncexitstack.py", line 18, in __call__
    await self.app(scope, receive, send)
  File "/usr/local/lib/python3.10/site-packages/starlette/routing.py", line 706, in __call__
    await route.handle(scope, receive, send)
  File "/usr/local/lib/python3.10/site-packages/starlette/routing.py", line 276, in handle
    await self.app(scope, receive, send)
  File "/usr/local/lib/python3.10/site-packages/starlette/routing.py", line 69, in app
    await response(scope, receive, send)
  File "/usr/local/lib/python3.10/site-packages/starlette/responses.py", line 334, in __call__
    raise RuntimeError(f"File at path {self.path} does not exist.")
RuntimeError: File at path /usr/src/app/edited_file.xlsx does not exist.
ERROR:    Exception in ASGI application
Traceback (most recent call last):
  File "/usr/local/lib/python3.10/site-packages/starlette/responses.py", line 331, in __call__
    stat_result = await anyio.to_thread.run_sync(os.stat, self.path)
  File "/usr/local/lib/python3.10/site-packages/anyio/to_thread.py", line 31, in run_sync
    return await get_asynclib().run_sync_in_worker_thread(
  File "/usr/local/lib/python3.10/site-packages/anyio/_backends/_asyncio.py", line 937, in run_sync_in_worker_thread
    return await future
  File "/usr/local/lib/python3.10/site-packages/anyio/_backends/_asyncio.py", line 867, in run
    result = context.run(func, *args)
FileNotFoundError: [Errno 2] No such file or directory: '/usr/src/app/edited_file.xlsx'

During handling of the above exception, another exception occurred:

Traceback (most recent call last):
  File "/usr/local/lib/python3.10/site-packages/uvicorn/protocols/http/httptools_impl.py", line 419, in run_asgi
    result = await app(  # type: ignore[func-returns-value]
  File "/usr/local/lib/python3.10/site-packages/uvicorn/middleware/proxy_headers.py", line 78, in __call__
    return await self.app(scope, receive, send)
  File "/usr/local/lib/python3.10/site-packages/fastapi/applications.py", line 270, in __call__
    await super().__call__(scope, receive, send)
  File "/usr/local/lib/python3.10/site-packages/starlette/applications.py", line 124, in __call__
    await self.middleware_stack(scope, receive, send)
  File "/usr/local/lib/python3.10/site-packages/starlette/middleware/errors.py", line 184, in __call__
    raise exc
  File "/usr/local/lib/python3.10/site-packages/starlette/middleware/errors.py", line 162, in __call__
    await self.app(scope, receive, _send)
  File "/usr/local/lib/python3.10/site-packages/starlette/middleware/cors.py", line 84, in __call__
    await self.app(scope, receive, send)
  File "/usr/local/lib/python3.10/site-packages/starlette/middleware/exceptions.py", line 79, in __call__
    raise exc
  File "/usr/local/lib/python3.10/site-packages/starlette/middleware/exceptions.py", line 68, in __call__
    await self.app(scope, receive, sender)
  File "/usr/local/lib/python3.10/site-packages/fastapi/middleware/asyncexitstack.py", line 21, in __call__
    raise e
  File "/usr/local/lib/python3.10/site-packages/fastapi/middleware/asyncexitstack.py", line 18, in __call__
    await self.app(scope, receive, send)
  File "/usr/local/lib/python3.10/site-packages/starlette/routing.py", line 706, in __call__
    await route.handle(scope, receive, send)
  File "/usr/local/lib/python3.10/site-packages/starlette/routing.py", line 276, in handle
    await self.app(scope, receive, send)
  File "/usr/local/lib/python3.10/site-packages/starlette/routing.py", line 69, in app
    await response(scope, receive, send)
  File "/usr/local/lib/python3.10/site-packages/starlette/responses.py", line 334, in __call__
    raise RuntimeError(f"File at path {self.path} does not exist.")
RuntimeError: File at path /usr/src/app/edited_file.xlsx does not exist.
ID:  892bc111-1ff5-44c8-b4ec-6fae1ac02010
Status:  SUCCESS
INFO:     172.23.0.6:57526 - "GET /queue/892bc111-1ff5-44c8-b4ec-6fae1ac02010 HTTP/1.0" 500 Internal Server Error
ID:  892bc111-1ff5-44c8-b4ec-6fae1ac02010
Status:  SUCCESS
INFO:     172.23.0.6:57528 - "GET /queue/892bc111-1ff5-44c8-b4ec-6fae1ac02010 HTTP/1.0" 500 Internal Server Error
ERROR:    Exception in ASGI application
Traceback (most recent call last):
  File "/usr/local/lib/python3.10/site-packages/starlette/responses.py", line 331, in __call__
    stat_result = await anyio.to_thread.run_sync(os.stat, self.path)
  File "/usr/local/lib/python3.10/site-packages/anyio/to_thread.py", line 31, in run_sync
    return await get_asynclib().run_sync_in_worker_thread(
  File "/usr/local/lib/python3.10/site-packages/anyio/_backends/_asyncio.py", line 937, in run_sync_in_worker_thread
    return await future
  File "/usr/local/lib/python3.10/site-packages/anyio/_backends/_asyncio.py", line 867, in run
    result = context.run(func, *args)
FileNotFoundError: [Errno 2] No such file or directory: '/usr/src/app/edited_file.xlsx'

During handling of the above exception, another exception occurred:

Traceback (most recent call last):
  File "/usr/local/lib/python3.10/site-packages/uvicorn/protocols/http/httptools_impl.py", line 419, in run_asgi
    result = await app(  # type: ignore[func-returns-value]
  File "/usr/local/lib/python3.10/site-packages/uvicorn/middleware/proxy_headers.py", line 78, in __call__
    return await self.app(scope, receive, send)
  File "/usr/local/lib/python3.10/site-packages/fastapi/applications.py", line 270, in __call__
    await super().__call__(scope, receive, send)
  File "/usr/local/lib/python3.10/site-packages/starlette/applications.py", line 124, in __call__
    await self.middleware_stack(scope, receive, send)
  File "/usr/local/lib/python3.10/site-packages/starlette/middleware/errors.py", line 184, in __call__
    raise exc
  File "/usr/local/lib/python3.10/site-packages/starlette/middleware/errors.py", line 162, in __call__
    await self.app(scope, receive, _send)
  File "/usr/local/lib/python3.10/site-packages/starlette/middleware/cors.py", line 84, in __call__
    await self.app(scope, receive, send)
  File "/usr/local/lib/python3.10/site-packages/starlette/middleware/exceptions.py", line 79, in __call__
    raise exc
  File "/usr/local/lib/python3.10/site-packages/starlette/middleware/exceptions.py", line 68, in __call__
    await self.app(scope, receive, sender)
  File "/usr/local/lib/python3.10/site-packages/fastapi/middleware/asyncexitstack.py", line 21, in __call__
    raise e
  File "/usr/local/lib/python3.10/site-packages/fastapi/middleware/asyncexitstack.py", line 18, in __call__
    await self.app(scope, receive, send)
  File "/usr/local/lib/python3.10/site-packages/starlette/routing.py", line 706, in __call__
    await route.handle(scope, receive, send)
  File "/usr/local/lib/python3.10/site-packages/starlette/routing.py", line 276, in handle
    await self.app(scope, receive, send)
  File "/usr/local/lib/python3.10/site-packages/starlette/routing.py", line 69, in app
    await response(scope, receive, send)
  File "/usr/local/lib/python3.10/site-packages/starlette/responses.py", line 334, in __call__
    raise RuntimeError(f"File at path {self.path} does not exist.")
RuntimeError: File at path /usr/src/app/edited_file.xlsx does not exist.
ERROR:    Exception in ASGI application
Traceback (most recent call last):
  File "/usr/local/lib/python3.10/site-packages/starlette/responses.py", line 331, in __call__
    stat_result = await anyio.to_thread.run_sync(os.stat, self.path)
  File "/usr/local/lib/python3.10/site-packages/anyio/to_thread.py", line 31, in run_sync
    return await get_asynclib().run_sync_in_worker_thread(
  File "/usr/local/lib/python3.10/site-packages/anyio/_backends/_asyncio.py", line 937, in run_sync_in_worker_thread
    return await future
  File "/usr/local/lib/python3.10/site-packages/anyio/_backends/_asyncio.py", line 867, in run
    result = context.run(func, *args)
FileNotFoundError: [Errno 2] No such file or directory: '/usr/src/app/edited_file.xlsx'

During handling of the above exception, another exception occurred:

Traceback (most recent call last):
  File "/usr/local/lib/python3.10/site-packages/uvicorn/protocols/http/httptools_impl.py", line 419, in run_asgi
    result = await app(  # type: ignore[func-returns-value]
  File "/usr/local/lib/python3.10/site-packages/uvicorn/middleware/proxy_headers.py", line 78, in __call__
    return await self.app(scope, receive, send)
ID:  892bc111-1ff5-44c8-b4ec-6fae1ac02010
Status:  SUCCESS
INFO:     172.23.0.6:57530 - "GET /queue/892bc111-1ff5-44c8-b4ec-6fae1ac02010 HTTP/1.0" 500 Internal Server Error
  File "/usr/local/lib/python3.10/site-packages/fastapi/applications.py", line 270, in __call__
    await super().__call__(scope, receive, send)
  File "/usr/local/lib/python3.10/site-packages/starlette/applications.py", line 124, in __call__
    await self.middleware_stack(scope, receive, send)
  File "/usr/local/lib/python3.10/site-packages/starlette/middleware/errors.py", line 184, in __call__
    raise exc
  File "/usr/local/lib/python3.10/site-packages/starlette/middleware/errors.py", line 162, in __call__
    await self.app(scope, receive, _send)
  File "/usr/local/lib/python3.10/site-packages/starlette/middleware/cors.py", line 84, in __call__
    await self.app(scope, receive, send)
  File "/usr/local/lib/python3.10/site-packages/starlette/middleware/exceptions.py", line 79, in __call__
    raise exc
  File "/usr/local/lib/python3.10/site-packages/starlette/middleware/exceptions.py", line 68, in __call__
    await self.app(scope, receive, sender)
  File "/usr/local/lib/python3.10/site-packages/fastapi/middleware/asyncexitstack.py", line 21, in __call__
    raise e
  File "/usr/local/lib/python3.10/site-packages/fastapi/middleware/asyncexitstack.py", line 18, in __call__
    await self.app(scope, receive, send)
  File "/usr/local/lib/python3.10/site-packages/starlette/routing.py", line 706, in __call__
    await route.handle(scope, receive, send)
  File "/usr/local/lib/python3.10/site-packages/starlette/routing.py", line 276, in handle
    await self.app(scope, receive, send)
  File "/usr/local/lib/python3.10/site-packages/starlette/routing.py", line 69, in app
    await response(scope, receive, send)
  File "/usr/local/lib/python3.10/site-packages/starlette/responses.py", line 334, in __call__
    raise RuntimeError(f"File at path {self.path} does not exist.")
RuntimeError: File at path /usr/src/app/edited_file.xlsx does not exist.
ERROR:    Exception in ASGI application
Traceback (most recent call last):
  File "/usr/local/lib/python3.10/site-packages/starlette/responses.py", line 331, in __call__
    stat_result = await anyio.to_thread.run_sync(os.stat, self.path)
  File "/usr/local/lib/python3.10/site-packages/anyio/to_thread.py", line 31, in run_sync
    return await get_asynclib().run_sync_in_worker_thread(
ID:  892bc111-1ff5-44c8-b4ec-6fae1ac02010
Status:  SUCCESS
INFO:     172.23.0.6:57532 - "GET /queue/892bc111-1ff5-44c8-b4ec-6fae1ac02010 HTTP/1.0" 500 Internal Server Error
  File "/usr/local/lib/python3.10/site-packages/anyio/_backends/_asyncio.py", line 937, in run_sync_in_worker_thread
    return await future
  File "/usr/local/lib/python3.10/site-packages/anyio/_backends/_asyncio.py", line 867, in run
    result = context.run(func, *args)
FileNotFoundError: [Errno 2] No such file or directory: '/usr/src/app/edited_file.xlsx'

During handling of the above exception, another exception occurred:

Traceback (most recent call last):
  File "/usr/local/lib/python3.10/site-packages/uvicorn/protocols/http/httptools_impl.py", line 419, in run_asgi
    result = await app(  # type: ignore[func-returns-value]
  File "/usr/local/lib/python3.10/site-packages/uvicorn/middleware/proxy_headers.py", line 78, in __call__
    return await self.app(scope, receive, send)
  File "/usr/local/lib/python3.10/site-packages/fastapi/applications.py", line 270, in __call__
    await super().__call__(scope, receive, send)
  File "/usr/local/lib/python3.10/site-packages/starlette/applications.py", line 124, in __call__
    await self.middleware_stack(scope, receive, send)
  File "/usr/local/lib/python3.10/site-packages/starlette/middleware/errors.py", line 184, in __call__
    raise exc
  File "/usr/local/lib/python3.10/site-packages/starlette/middleware/errors.py", line 162, in __call__
    await self.app(scope, receive, _send)
  File "/usr/local/lib/python3.10/site-packages/starlette/middleware/cors.py", line 84, in __call__
    await self.app(scope, receive, send)
  File "/usr/local/lib/python3.10/site-packages/starlette/middleware/exceptions.py", line 79, in __call__
    raise exc
  File "/usr/local/lib/python3.10/site-packages/starlette/middleware/exceptions.py", line 68, in __call__
    await self.app(scope, receive, sender)
  File "/usr/local/lib/python3.10/site-packages/fastapi/middleware/asyncexitstack.py", line 21, in __call__
    raise e
  File "/usr/local/lib/python3.10/site-packages/fastapi/middleware/asyncexitstack.py", line 18, in __call__
    await self.app(scope, receive, send)
  File "/usr/local/lib/python3.10/site-packages/starlette/routing.py", line 706, in __call__
    await route.handle(scope, receive, send)
  File "/usr/local/lib/python3.10/site-packages/starlette/routing.py", line 276, in handle
    await self.app(scope, receive, send)
  File "/usr/local/lib/python3.10/site-packages/starlette/routing.py", line 69, in app
    await response(scope, receive, send)
  File "/usr/local/lib/python3.10/site-packages/starlette/responses.py", line 334, in __call__
    raise RuntimeError(f"File at path {self.path} does not exist.")
RuntimeError: File at path /usr/src/app/edited_file.xlsx does not exist.
ERROR:    Exception in ASGI application
Traceback (most recent call last):
  File "/usr/local/lib/python3.10/site-packages/starlette/responses.py", line 331, in __call__
    stat_result = await anyio.to_thread.run_sync(os.stat, self.path)
  File "/usr/local/lib/python3.10/site-packages/anyio/to_thread.py", line 31, in run_sync
    return await get_asynclib().run_sync_in_worker_thread(
  File "/usr/local/lib/python3.10/site-packages/anyio/_backends/_asyncio.py", line 937, in run_sync_in_worker_thread
ID:  892bc111-1ff5-44c8-b4ec-6fae1ac02010
Status:  SUCCESS
INFO:     172.23.0.6:57534 - "GET /queue/892bc111-1ff5-44c8-b4ec-6fae1ac02010 HTTP/1.0" 500 Internal Server Error
    return await future
  File "/usr/local/lib/python3.10/site-packages/anyio/_backends/_asyncio.py", line 867, in run
    result = context.run(func, *args)
FileNotFoundError: [Errno 2] No such file or directory: '/usr/src/app/edited_file.xlsx'

During handling of the above exception, another exception occurred:

Traceback (most recent call last):
  File "/usr/local/lib/python3.10/site-packages/uvicorn/protocols/http/httptools_impl.py", line 419, in run_asgi
    result = await app(  # type: ignore[func-returns-value]
  File "/usr/local/lib/python3.10/site-packages/uvicorn/middleware/proxy_headers.py", line 78, in __call__
    return await self.app(scope, receive, send)
  File "/usr/local/lib/python3.10/site-packages/fastapi/applications.py", line 270, in __call__
    await super().__call__(scope, receive, send)
  File "/usr/local/lib/python3.10/site-packages/starlette/applications.py", line 124, in __call__
    await self.middleware_stack(scope, receive, send)
  File "/usr/local/lib/python3.10/site-packages/starlette/middleware/errors.py", line 184, in __call__
    raise exc
  File "/usr/local/lib/python3.10/site-packages/starlette/middleware/errors.py", line 162, in __call__
    await self.app(scope, receive, _send)
  File "/usr/local/lib/python3.10/site-packages/starlette/middleware/cors.py", line 84, in __call__
    await self.app(scope, receive, send)
  File "/usr/local/lib/python3.10/site-packages/starlette/middleware/exceptions.py", line 79, in __call__
    raise exc
  File "/usr/local/lib/python3.10/site-packages/starlette/middleware/exceptions.py", line 68, in __call__
    await self.app(scope, receive, sender)
  File "/usr/local/lib/python3.10/site-packages/fastapi/middleware/asyncexitstack.py", line 21, in __call__
    raise e
  File "/usr/local/lib/python3.10/site-packages/fastapi/middleware/asyncexitstack.py", line 18, in __call__
    await self.app(scope, receive, send)
  File "/usr/local/lib/python3.10/site-packages/starlette/routing.py", line 706, in __call__
    await route.handle(scope, receive, send)
  File "/usr/local/lib/python3.10/site-packages/starlette/routing.py", line 276, in handle
    await self.app(scope, receive, send)
  File "/usr/local/lib/python3.10/site-packages/starlette/routing.py", line 69, in app
    await response(scope, receive, send)
  File "/usr/local/lib/python3.10/site-packages/starlette/responses.py", line 334, in __call__
    raise RuntimeError(f"File at path {self.path} does not exist.")
RuntimeError: File at path /usr/src/app/edited_file.xlsx does not exist.
ERROR:    Exception in ASGI application
Traceback (most recent call last):
  File "/usr/local/lib/python3.10/site-packages/starlette/responses.py", line 331, in __call__
    stat_result = await anyio.to_thread.run_sync(os.stat, self.path)
  File "/usr/local/lib/python3.10/site-packages/anyio/to_thread.py", line 31, in run_sync
    return await get_asynclib().run_sync_in_worker_thread(
  File "/usr/local/lib/python3.10/site-packages/anyio/_backends/_asyncio.py", line 937, in run_sync_in_worker_thread
    return await future
  File "/usr/local/lib/python3.10/site-packages/anyio/_backends/_asyncio.py", line 867, in run
    result = context.run(func, *args)
FileNotFoundError: [Errno 2] No such file or directory: '/usr/src/app/edited_file.xlsx'

During handling of the above exception, another exception occurred:

Traceback (most recent call last):
  File "/usr/local/lib/python3.10/site-packages/uvicorn/protocols/http/httptools_impl.py", line 419, in run_asgi
    result = await app(  # type: ignore[func-returns-value]
  File "/usr/local/lib/python3.10/site-packages/uvicorn/middleware/proxy_headers.py", line 78, in __call__
    return await self.app(scope, receive, send)
  File "/usr/local/lib/python3.10/site-packages/fastapi/applications.py", line 270, in __call__
    await super().__call__(scope, receive, send)
  File "/usr/local/lib/python3.10/site-packages/starlette/applications.py", line 124, in __call__
    await self.middleware_stack(scope, receive, send)
  File "/usr/local/lib/python3.10/site-packages/starlette/middleware/errors.py", line 184, in __call__
    raise exc
  File "/usr/local/lib/python3.10/site-packages/starlette/middleware/errors.py", line 162, in __call__
    await self.app(scope, receive, _send)
  File "/usr/local/lib/python3.10/site-packages/starlette/middleware/cors.py", line 84, in __call__
    await self.app(scope, receive, send)
  File "/usr/local/lib/python3.10/site-packages/starlette/middleware/exceptions.py", line 79, in __call__
    raise exc
  File "/usr/local/lib/python3.10/site-packages/starlette/middleware/exceptions.py", line 68, in __call__
    await self.app(scope, receive, sender)
  File "/usr/local/lib/python3.10/site-packages/fastapi/middleware/asyncexitstack.py", line 21, in __call__
    raise e
  File "/usr/local/lib/python3.10/site-packages/fastapi/middleware/asyncexitstack.py", line 18, in __call__
    await self.app(scope, receive, send)
  File "/usr/local/lib/python3.10/site-packages/starlette/routing.py", line 706, in __call__
    await route.handle(scope, receive, send)
  File "/usr/local/lib/python3.10/site-packages/starlette/routing.py", line 276, in handle
ID:  892bc111-1ff5-44c8-b4ec-6fae1ac02010
Status:  SUCCESS
INFO:     172.23.0.6:57536 - "GET /queue/892bc111-1ff5-44c8-b4ec-6fae1ac02010 HTTP/1.0" 500 Internal Server Error
ID:  892bc111-1ff5-44c8-b4ec-6fae1ac02010
Status:  SUCCESS
INFO:     172.23.0.6:57538 - "GET /queue/892bc111-1ff5-44c8-b4ec-6fae1ac02010 HTTP/1.0" 500 Internal Server Error
ID:  892bc111-1ff5-44c8-b4ec-6fae1ac02010
Status:  SUCCESS
INFO:     172.23.0.6:57540 - "GET /queue/892bc111-1ff5-44c8-b4ec-6fae1ac02010 HTTP/1.0" 500 Internal Server Error
    await self.app(scope, receive, send)
  File "/usr/local/lib/python3.10/site-packages/starlette/routing.py", line 69, in app
    await response(scope, receive, send)
  File "/usr/local/lib/python3.10/site-packages/starlette/responses.py", line 334, in __call__
    raise RuntimeError(f"File at path {self.path} does not exist.")
RuntimeError: File at path /usr/src/app/edited_file.xlsx does not exist.
ERROR:    Exception in ASGI application
Traceback (most recent call last):
  File "/usr/local/lib/python3.10/site-packages/starlette/responses.py", line 331, in __call__
    stat_result = await anyio.to_thread.run_sync(os.stat, self.path)
  File "/usr/local/lib/python3.10/site-packages/anyio/to_thread.py", line 31, in run_sync
    return await get_asynclib().run_sync_in_worker_thread(
  File "/usr/local/lib/python3.10/site-packages/anyio/_backends/_asyncio.py", line 937, in run_sync_in_worker_thread
    return await future
  File "/usr/local/lib/python3.10/site-packages/anyio/_backends/_asyncio.py", line 867, in run
    result = context.run(func, *args)
FileNotFoundError: [Errno 2] No such file or directory: '/usr/src/app/edited_file.xlsx'

During handling of the above exception, another exception occurred:

Traceback (most recent call last):
  File "/usr/local/lib/python3.10/site-packages/uvicorn/protocols/http/httptools_impl.py", line 419, in run_asgi
    result = await app(  # type: ignore[func-returns-value]
  File "/usr/local/lib/python3.10/site-packages/uvicorn/middleware/proxy_headers.py", line 78, in __call__
    return await self.app(scope, receive, send)
  File "/usr/local/lib/python3.10/site-packages/fastapi/applications.py", line 270, in __call__
    await super().__call__(scope, receive, send)
  File "/usr/local/lib/python3.10/site-packages/starlette/applications.py", line 124, in __call__
    await self.middleware_stack(scope, receive, send)
  File "/usr/local/lib/python3.10/site-packages/starlette/middleware/errors.py", line 184, in __call__
    raise exc
  File "/usr/local/lib/python3.10/site-packages/starlette/middleware/errors.py", line 162, in __call__
    await self.app(scope, receive, _send)
  File "/usr/local/lib/python3.10/site-packages/starlette/middleware/cors.py", line 84, in __call__
    await self.app(scope, receive, send)
  File "/usr/local/lib/python3.10/site-packages/starlette/middleware/exceptions.py", line 79, in __call__
    raise exc
  File "/usr/local/lib/python3.10/site-packages/starlette/middleware/exceptions.py", line 68, in __call__
    await self.app(scope, receive, sender)
  File "/usr/local/lib/python3.10/site-packages/fastapi/middleware/asyncexitstack.py", line 21, in __call__
    raise e
  File "/usr/local/lib/python3.10/site-packages/fastapi/middleware/asyncexitstack.py", line 18, in __call__
    await self.app(scope, receive, send)
  File "/usr/local/lib/python3.10/site-packages/starlette/routing.py", line 706, in __call__
    await route.handle(scope, receive, send)
  File "/usr/local/lib/python3.10/site-packages/starlette/routing.py", line 276, in handle
    await self.app(scope, receive, send)
  File "/usr/local/lib/python3.10/site-packages/starlette/routing.py", line 69, in app
    await response(scope, receive, send)
  File "/usr/local/lib/python3.10/site-packages/starlette/responses.py", line 334, in __call__
    raise RuntimeError(f"File at path {self.path} does not exist.")
RuntimeError: File at path /usr/src/app/edited_file.xlsx does not exist.
ERROR:    Exception in ASGI application
Traceback (most recent call last):
  File "/usr/local/lib/python3.10/site-packages/starlette/responses.py", line 331, in __call__
    stat_result = await anyio.to_thread.run_sync(os.stat, self.path)
  File "/usr/local/lib/python3.10/site-packages/anyio/to_thread.py", line 31, in run_sync
    return await get_asynclib().run_sync_in_worker_thread(
  File "/usr/local/lib/python3.10/site-packages/anyio/_backends/_asyncio.py", line 937, in run_sync_in_worker_thread
    return await future
  File "/usr/local/lib/python3.10/site-packages/anyio/_backends/_asyncio.py", line 867, in run
    result = context.run(func, *args)
FileNotFoundError: [Errno 2] No such file or directory: '/usr/src/app/edited_file.xlsx'

During handling of the above exception, another exception occurred:

Traceback (most recent call last):
  File "/usr/local/lib/python3.10/site-packages/uvicorn/protocols/http/httptools_impl.py", line 419, in run_asgi
    result = await app(  # type: ignore[func-returns-value]
  File "/usr/local/lib/python3.10/site-packages/uvicorn/middleware/proxy_headers.py", line 78, in __call__
    return await self.app(scope, receive, send)
  File "/usr/local/lib/python3.10/site-packages/fastapi/applications.py", line 270, in __call__
    await super().__call__(scope, receive, send)
  File "/usr/local/lib/python3.10/site-packages/starlette/applications.py", line 124, in __call__
    await self.middleware_stack(scope, receive, send)
  File "/usr/local/lib/python3.10/site-packages/starlette/middleware/errors.py", line 184, in __call__
    raise exc
  File "/usr/local/lib/python3.10/site-packages/starlette/middleware/errors.py", line 162, in __call__
    await self.app(scope, receive, _send)
  File "/usr/local/lib/python3.10/site-packages/starlette/middleware/cors.py", line 84, in __call__
    await self.app(scope, receive, send)
  File "/usr/local/lib/python3.10/site-packages/starlette/middleware/exceptions.py", line 79, in __call__
    raise exc
  File "/usr/local/lib/python3.10/site-packages/starlette/middleware/exceptions.py", line 68, in __call__
    await self.app(scope, receive, sender)
  File "/usr/local/lib/python3.10/site-packages/fastapi/middleware/asyncexitstack.py", line 21, in __call__
    raise e
  File "/usr/local/lib/python3.10/site-packages/fastapi/middleware/asyncexitstack.py", line 18, in __call__
    await self.app(scope, receive, send)
  File "/usr/local/lib/python3.10/site-packages/starlette/routing.py", line 706, in __call__
    await route.handle(scope, receive, send)
  File "/usr/local/lib/python3.10/site-packages/starlette/routing.py", line 276, in handle
    await self.app(scope, receive, send)
  File "/usr/local/lib/python3.10/site-packages/starlette/routing.py", line 69, in app
    await response(scope, receive, send)
  File "/usr/local/lib/python3.10/site-packages/starlette/responses.py", line 334, in __call__
    raise RuntimeError(f"File at path {self.path} does not exist.")
RuntimeError: File at path /usr/src/app/edited_file.xlsx does not exist.
ERROR:    Exception in ASGI application
Traceback (most recent call last):
  File "/usr/local/lib/python3.10/site-packages/starlette/responses.py", line 331, in __call__
    stat_result = await anyio.to_thread.run_sync(os.stat, self.path)
  File "/usr/local/lib/python3.10/site-packages/anyio/to_thread.py", line 31, in run_sync
    return await get_asynclib().run_sync_in_worker_thread(
  File "/usr/local/lib/python3.10/site-packages/anyio/_backends/_asyncio.py", line 937, in run_sync_in_worker_thread
    return await future
  File "/usr/local/lib/python3.10/site-packages/anyio/_backends/_asyncio.py", line 867, in run
    result = context.run(func, *args)
FileNotFoundError: [Errno 2] No such file or directory: '/usr/src/app/edited_file.xlsx'

During handling of the above exception, another exception occurred:
ID:  2169bd28-eb05-43f3-aee0-6e69bc722dba
Filepath:  /usr/src/app/7718d912-906c-4198-b9db-1fe65d3606d0.xlsx
INFO:     172.23.0.6:57562 - "POST /task/excel/uploadfile_with_progress HTTP/1.0" 202 Accepted
ID:  2169bd28-eb05-43f3-aee0-6e69bc722dba
Status:  PENDING
INFO:     172.23.0.6:57564 - "GET /queue/2169bd28-eb05-43f3-aee0-6e69bc722dba HTTP/1.0" 200 OK
ID:  167d13c3-c11d-4411-92d2-973c74bd3227
Filepath:  /usr/src/app/41bd269b-b36f-426b-9467-c9e7fc3f82cb.xlsx
INFO:     172.23.0.6:57580 - "POST /task/excel/uploadfile_with_progress HTTP/1.0" 202 Accepted
ID:  167d13c3-c11d-4411-92d2-973c74bd3227
Status:  PENDING
INFO:     172.23.0.6:57582 - "GET /queue/167d13c3-c11d-4411-92d2-973c74bd3227 HTTP/1.0" 200 OK
ID:  feeea429-bd69-40be-a70f-a5419f204bc4
Filepath:  /usr/src/app/393b55bc-9c5c-4f39-9f87-d4f623e1565d.xlsx
INFO:     172.23.0.6:57596 - "POST /task/excel/uploadfile_with_progress HTTP/1.0" 202 Accepted
ID:  feeea429-bd69-40be-a70f-a5419f204bc4
Status:  PENDING
INFO:     172.23.0.6:57598 - "GET /queue/feeea429-bd69-40be-a70f-a5419f204bc4 HTTP/1.0" 200 OK
ID:  feeea429-bd69-40be-a70f-a5419f204bc4
Status:  SUCCESS
INFO:     172.23.0.6:57600 - "GET /queue/feeea429-bd69-40be-a70f-a5419f204bc4 HTTP/1.0" 200 OK
ID:  feeea429-bd69-40be-a70f-a5419f204bc4
Status:  SUCCESS
INFO:     172.23.0.6:57602 - "GET /queue/feeea429-bd69-40be-a70f-a5419f204bc4 HTTP/1.0" 500 Internal Server Error

Traceback (most recent call last):
  File "/usr/local/lib/python3.10/site-packages/uvicorn/protocols/http/httptools_impl.py", line 419, in run_asgi
    result = await app(  # type: ignore[func-returns-value]
  File "/usr/local/lib/python3.10/site-packages/uvicorn/middleware/proxy_headers.py", line 78, in __call__
    return await self.app(scope, receive, send)
  File "/usr/local/lib/python3.10/site-packages/fastapi/applications.py", line 270, in __call__
    await super().__call__(scope, receive, send)
  File "/usr/local/lib/python3.10/site-packages/starlette/applications.py", line 124, in __call__
    await self.middleware_stack(scope, receive, send)
  File "/usr/local/lib/python3.10/site-packages/starlette/middleware/errors.py", line 184, in __call__
    raise exc
  File "/usr/local/lib/python3.10/site-packages/starlette/middleware/errors.py", line 162, in __call__
    await self.app(scope, receive, _send)
  File "/usr/local/lib/python3.10/site-packages/starlette/middleware/cors.py", line 84, in __call__
    await self.app(scope, receive, send)
  File "/usr/local/lib/python3.10/site-packages/starlette/middleware/exceptions.py", line 79, in __call__
    raise exc
  File "/usr/local/lib/python3.10/site-packages/starlette/middleware/exceptions.py", line 68, in __call__
    await self.app(scope, receive, sender)
  File "/usr/local/lib/python3.10/site-packages/fastapi/middleware/asyncexitstack.py", line 21, in __call__
    raise e
  File "/usr/local/lib/python3.10/site-packages/fastapi/middleware/asyncexitstack.py", line 18, in __call__
    await self.app(scope, receive, send)
  File "/usr/local/lib/python3.10/site-packages/starlette/routing.py", line 706, in __call__
    await route.handle(scope, receive, send)
  File "/usr/local/lib/python3.10/site-packages/starlette/routing.py", line 276, in handle
    await self.app(scope, receive, send)
  File "/usr/local/lib/python3.10/site-packages/starlette/routing.py", line 69, in app
    await response(scope, receive, send)
  File "/usr/local/lib/python3.10/site-packages/starlette/responses.py", line 334, in __call__
    raise RuntimeError(f"File at path {self.path} does not exist.")
RuntimeError: File at path /usr/src/app/edited_file.xlsx does not exist.
ERROR:    Exception in ASGI application
Traceback (most recent call last):
  File "/usr/local/lib/python3.10/site-packages/uvicorn/protocols/http/httptools_impl.py", line 419, in run_asgi
    result = await app(  # type: ignore[func-returns-value]
  File "/usr/local/lib/python3.10/site-packages/uvicorn/middleware/proxy_headers.py", line 78, in __call__
    return await self.app(scope, receive, send)
  File "/usr/local/lib/python3.10/site-packages/fastapi/applications.py", line 270, in __call__
    await super().__call__(scope, receive, send)
  File "/usr/local/lib/python3.10/site-packages/starlette/applications.py", line 124, in __call__
    await self.middleware_stack(scope, receive, send)
  File "/usr/local/lib/python3.10/site-packages/starlette/middleware/errors.py", line 184, in __call__
    raise exc
  File "/usr/local/lib/python3.10/site-packages/starlette/middleware/errors.py", line 162, in __call__
    await self.app(scope, receive, _send)
  File "/usr/local/lib/python3.10/site-packages/starlette/middleware/cors.py", line 92, in __call__
    await self.simple_response(scope, receive, send, request_headers=headers)
  File "/usr/local/lib/python3.10/site-packages/starlette/middleware/cors.py", line 147, in simple_response
    await self.app(scope, receive, send)
  File "/usr/local/lib/python3.10/site-packages/starlette/middleware/exceptions.py", line 79, in __call__
    raise exc
  File "/usr/local/lib/python3.10/site-packages/starlette/middleware/exceptions.py", line 68, in __call__
    await self.app(scope, receive, sender)
  File "/usr/local/lib/python3.10/site-packages/fastapi/middleware/asyncexitstack.py", line 21, in __call__
    raise e
  File "/usr/local/lib/python3.10/site-packages/fastapi/middleware/asyncexitstack.py", line 18, in __call__
    await self.app(scope, receive, send)
  File "/usr/local/lib/python3.10/site-packages/starlette/routing.py", line 706, in __call__
    await route.handle(scope, receive, send)
  File "/usr/local/lib/python3.10/site-packages/starlette/routing.py", line 276, in handle
    await self.app(scope, receive, send)
  File "/usr/local/lib/python3.10/site-packages/starlette/routing.py", line 66, in app
    response = await func(request)
  File "/usr/local/lib/python3.10/site-packages/fastapi/routing.py", line 237, in app
    raw_response = await run_endpoint_function(
  File "/usr/local/lib/python3.10/site-packages/fastapi/routing.py", line 163, in run_endpoint_function
    return await dependant.call(**values)
  File "/code/./app/main.py", line 73, in excel_task
    wb: Workbook = load_workbook(xlsx)
  File "/usr/local/lib/python3.10/site-packages/openpyxl/reader/excel.py", line 315, in load_workbook
    reader = ExcelReader(filename, read_only, keep_vba,
  File "/usr/local/lib/python3.10/site-packages/openpyxl/reader/excel.py", line 124, in __init__
    self.archive = _validate_archive(fn)
  File "/usr/local/lib/python3.10/site-packages/openpyxl/reader/excel.py", line 96, in _validate_archive
    archive = ZipFile(filename, 'r')
  File "/usr/local/lib/python3.10/zipfile.py", line 1267, in __init__
    self._RealGetContents()
  File "/usr/local/lib/python3.10/zipfile.py", line 1364, in _RealGetContents
    raise BadZipFile("Bad magic number for central directory")
zipfile.BadZipFile: Bad magic number for central directory
ERROR:    Exception in ASGI application
Traceback (most recent call last):
  File "/usr/local/lib/python3.10/site-packages/uvicorn/protocols/http/httptools_impl.py", line 419, in run_asgi
    result = await app(  # type: ignore[func-returns-value]
  File "/usr/local/lib/python3.10/site-packages/uvicorn/middleware/proxy_headers.py", line 78, in __call__
    return await self.app(scope, receive, send)
  File "/usr/local/lib/python3.10/site-packages/fastapi/applications.py", line 270, in __call__
    await super().__call__(scope, receive, send)
  File "/usr/local/lib/python3.10/site-packages/starlette/applications.py", line 124, in __call__
    await self.middleware_stack(scope, receive, send)
  File "/usr/local/lib/python3.10/site-packages/starlette/middleware/errors.py", line 184, in __call__
    raise exc
  File "/usr/local/lib/python3.10/site-packages/starlette/middleware/errors.py", line 162, in __call__
    await self.app(scope, receive, _send)
  File "/usr/local/lib/python3.10/site-packages/starlette/middleware/cors.py", line 92, in __call__
    await self.simple_response(scope, receive, send, request_headers=headers)
  File "/usr/local/lib/python3.10/site-packages/starlette/middleware/cors.py", line 147, in simple_response
    await self.app(scope, receive, send)
  File "/usr/local/lib/python3.10/site-packages/starlette/middleware/exceptions.py", line 79, in __call__
    raise exc
  File "/usr/local/lib/python3.10/site-packages/starlette/middleware/exceptions.py", line 68, in __call__
    await self.app(scope, receive, sender)
  File "/usr/local/lib/python3.10/site-packages/fastapi/middleware/asyncexitstack.py", line 21, in __call__
    raise e
  File "/usr/local/lib/python3.10/site-packages/fastapi/middleware/asyncexitstack.py", line 18, in __call__
    await self.app(scope, receive, send)
  File "/usr/local/lib/python3.10/site-packages/starlette/routing.py", line 706, in __call__
    await route.handle(scope, receive, send)
INFO:     172.23.0.6:57610 - "POST /task/excel/uploadfile HTTP/1.0" 200 OK
INFO:     172.23.0.6:57634 - "POST /task/excel/uploadfile HTTP/1.0" 200 OK
INFO:     172.23.0.6:57636 - "POST /task/excel/uploadfile HTTP/1.0" 200 OK
INFO:     172.23.0.6:57650 - "POST /task/excel/uploadfile HTTP/1.0" 200 OK
INFO:     172.23.0.6:57662 - "POST /task/excel/uploadfile HTTP/1.0" 200 OK
INFO:     172.23.0.6:57674 - "POST /task/excel/uploadfile HTTP/1.0" 500 Internal Server Error
INFO:     172.23.0.6:57676 - "POST /task/excel/uploadfile HTTP/1.0" 500 Internal Server Error
  File "/usr/local/lib/python3.10/site-packages/starlette/routing.py", line 276, in handle
    await self.app(scope, receive, send)
  File "/usr/local/lib/python3.10/site-packages/starlette/routing.py", line 66, in app
    response = await func(request)
  File "/usr/local/lib/python3.10/site-packages/fastapi/routing.py", line 237, in app
    raw_response = await run_endpoint_function(
  File "/usr/local/lib/python3.10/site-packages/fastapi/routing.py", line 163, in run_endpoint_function
    return await dependant.call(**values)
  File "/code/./app/main.py", line 73, in excel_task
    wb: Workbook = load_workbook(xlsx)
  File "/usr/local/lib/python3.10/site-packages/openpyxl/reader/excel.py", line 315, in load_workbook
    reader = ExcelReader(filename, read_only, keep_vba,
  File "/usr/local/lib/python3.10/site-packages/openpyxl/reader/excel.py", line 124, in __init__
    self.archive = _validate_archive(fn)
  File "/usr/local/lib/python3.10/site-packages/openpyxl/reader/excel.py", line 96, in _validate_archive
    archive = ZipFile(filename, 'r')
  File "/usr/local/lib/python3.10/zipfile.py", line 1267, in __init__
    self._RealGetContents()
  File "/usr/local/lib/python3.10/zipfile.py", line 1353, in _RealGetContents
    raise BadZipFile("Bad offset for central directory")
zipfile.BadZipFile: Bad offset for central directory